Workbook

Sheet Sheet2
A3: country | B3: Average of order_total
A4: uk | B4: 94.271053
A5: direct | B5: 52.25
A6: email | B6: 98.214286
A7: organic | B7: 145.66667
A8: paid_search | B8: 186.575 | C8: order date | D8: Sum of order_total
A9: social | B9: -118.2 | C9: 01/13/2026 | D9: 387
A10: France | B10: 100.86591 | C10: refunded | D10: 387
A11: direct | B11: 70.5 | C11: 01-02-2026 | D11: 447
A12: email | B12: 163 | C12: completed | D12: 447
A13: organic | B13: 29.42 | C13: 01-03-2026 | D13: -22.35
A14: paid_search | B14: 138.04375 | C14: completed | D14: -22.35
A15: social | B15: 107.525 | C15: 01-04-2026 | D15: -219
A16: Ireland | B16: 113.81585 | C16: completed | D16: -219
A17: direct | B17: 120.31818 | C17: 01-05-2026 | D17: 171
A18: email | B18: 114.62 | C18: completed | D18: 171
A19: organic | B19: 109.1875 | C19: 01-07-2026 | D19: 129
A20: paid_search | B20: 158.57778 | C20: completed | D20: 129 | F20: currency | G20: Sum of order_total
A21: social | B21: 58.64375 | C21: 02/14/2026 | D21: 80.1 | F21: EUR | G21: 4900.9
A22: UK | B22: 118.07222 | C22: completed | D22: 80.1 | F22: direct | G22: 1067.1
A23: direct | B23: 193.2 | C23: 02/19/2026 | D23: 79 | F23: email | G23: 1219.4
A24: email | B24: 112.35 | C24: completed | D24: 79 | F24: organic | G24: 704.3
A25: organic | B25: 109.73333 | C25: 02/27/2026 | D25: 348.3 | F25: paid_search | G25: 975.8
A26: paid_search | B26: 112.06667 | C26: refunded | D26: 348.3 | F26: social | G26: 934.3
A27: social | B27: 68.733333 | C27: 02-02-2026 | D27: 80.1 | F27: GBP | G27: 20803.15
A28: GB | B28: 126.50833 | C28: completed | D28: 80.1 | F28: direct | G28: 3064.45
A29: direct | B29: 124.685 | C29: 02-04-2026 | D29: 135.5 | F29: email | G29: 3525.15
A30: email | B30: 109.5 | C30: completed | D30: 135.5 | F30: organic | G30: 5375.8
A31: organic | B31: 110.58125 | C31: 02-05-2026 | D31: 232.2 | F31: paid_search | G31: 5744.4
A32: paid_search | B32: 159.03333 | C32: completed | D32: 232.2 | F32: social | G32: 3093.35
A33: social | B33: 104.43125 | C33: 02-07-2026 | D33: 230 | F33: Grand Total | G33: 25704.05
A34: UK | B34: 148.68276 | C34: completed | D34: 149
A35: direct | B35: 185.4 | C35: refunded | D35: 81
A36: email | B36: 97.383333 | C36: 03/14/2026 | D36: 90
A37: organic | B37: 192.34444 | C37: completed | D37: 90
A38: paid_search | B38: 77.1 | C38: 03/15/2026 | D38: 237
A39: social | B39: 177.15714 | C39: refunded | D39: 237
A40: United Kingdom | B40: 159.3125 | C40: 03/19/2026 | D40: 447
A41: direct | B41: 115.65 | C41: completed | D41: 447
A42: email | B42: 258.7 | C42: 03/21/2026 | D42: 21.6
...

Sheet ecommerce-order (1)
A1: order_id | B1: order_date | C1: customer_email | D1: country | E1: channel | F1: product_sku | G1: product_name | H1: quantity | I1: unit_price | J1: order_total | K1: weight | L1: currency | M1: status | N1: unit_price_fixed | O1: aggregate functions | P1: aggregate function name | Q1: vlookup
A2: ORD-101805 | B2: 19-03-2026 | C2: customer0457@example.com | D2: France | E2: direct | F2: FR-9902 | G2: Trekking Poles | H2: 1 | I2: 45 | J2: 36 | K2: 520 | L2: EUR | M2: completed | N2: 45 | O2: =SUM(J:J) -> 25704.05 | P2: sum | Q2: =VLOOKUP(ecommerce_order__1[[#This Row],[product_sku]],F:J,5,FALSE) -> 36
A3: ORD-102690 | B3: 19-05-2026 | C3: customer0814@example.com | D3: France | E3: social | F3: FR-2210 | G3: Trail Softshell | H3: 1 | I3: 71.1 | J3: 71.1 | K3: 0.52 | L3: GBP | M3: completed | N3: 71.1 | O3: =MAX(J:J) -> 447 | P3: max | Q3: =VLOOKUP(ecommerce_order__1[[#This Row],[product_sku]],F:J,5,FALSE) -> 71.1
A4: ORD-101454 | B4: 14-06-2026 | C4: customer0858@example.com | D4: UK | E4: email | F4: FR-1120 | G4: Fell Runner Cap | H4: 1 | J4: 45 | K4: 0.085 | L4: GBP | M4: completed | N4: 45 | O4: =MIN(J:J) -> -258 | P4: min | Q4: =VLOOKUP(ecommerce_order__1[[#This Row],[product_sku]],F:J,5,FALSE) -> 45
A5: ORD-100450 | B5: 08-01-2026 | C5: customer0116@example.com | D5: UK | E5: organic | F5: FR-5567 | G5: Merino Base Layer | H5: 1 | I5: 71.1 | J5: 71.1 | K5: 190 | L5: EUR | M5: completed | N5: 71.1 | O5: =COUNT(J:J) -> 202 | P5: count | Q5: =VLOOKUP(ecommerce_order__1[[#This Row],[product_sku]],F:J,5,FALSE) -> 71.1
A6: ORD-101501 | B6: 20-05-2026 | C6: customer1397@example.com | D6: Ireland | E6: email | F6: FR-8890 | G6: Summit Down Gilet | H6: 1 | I6: 21.6 | J6: 21.6 | K6: 0.38 | L6: GBP | M6: completed | N6: 21.6 | O6: =COUNTIF(J:J,">200") -> 45 | P6: count if | Q6: =VLOOKUP(ecommerce_order__1[[#This Row],[product_sku]],F:J,5,FALSE) -> 21.6
A7: ORD-101788 | B7: 14-03-2026 | C7: customer0775@example.com | D7: GB | E7: organic | F7: FR-1120 | G7: Fell Runner Cap | H7: 1 | I7: 45 | J7: 45 | K7: 85 | L7: GBP | M7: completed | N7: 45 | Q7: =VLOOKUP(ecommerce_order__1[[#This Row],[product_sku]],F:J,5,FALSE) -> 45
A8: ORD-102657 | B8: 25-04-2026 | C8: customer1328@example.com | D8: GB | E8: social | F8: FR-1120 | G8: Fell Runner Cap | H8: 3 | I8: 85.5 | J8: 256.5 | K8: 0.085 | L8: GBP | M8: refunded | N8: 85.5 | Q8: =VLOOKUP(ecommerce_order__1[[#This Row],[product_sku]],F:J,5,FALSE) -> 45
A9: ORD-102047 | B9: 20-05-2026 | C9: customer0760@example.com | D9: ireland | E9: organic | F9: FR-1120 | G9: Fell Runner Cap | H9: 2 | I9: 134.1 | J9: 268.2 | K9: 0.085 | L9: EUR | M9: refunded | N9: 134.1 | Q9: =VLOOKUP(ecommerce_order__1[[#This Row],[product_sku]],F:J,5,FALSE) -> 45
A10: ORD-102650 | B10: 02-04-2026 | C10: customer0013@example.com | D10: gb | E10: paid_search | F10: FR-5567 | G10: Merino Base Layer | H10: 1 | I10: 24 | J10: 24 | K10: 190 | L10: GBP | M10: completed | N10: 24 | Q10: =VLOOKUP(ecommerce_order__1[[#This Row],[product_sku]],F:J,5,FALSE) -> 71.1
A11: ORD-102734 | B11: 16-02-2026 | C11: customer0805@example.com | D11: UK | E11: paid_search | F11: FR-5567 | G11: Merino Base Layer | H11: 1 | I11: 95 | J11: 95 | K11: 190 | L11: EUR | M11: refunded | N11: 95 | Q11: =VLOOKUP(ecommerce_order__1[[#This Row],[product_sku]],F:J,5,FALSE) -> 71.1
A12: ORD-102012 | B12: 21-04-2026 | C12: customer0123@example.com | D12: UK | E12: email | F12: FR-7781 | G12: Storm Overtrousers | H12: 1 | I12: 45 | J12: 45 | K12: 0.41 | L12: GBP | M12: completed | N12: 45 | Q12: =VLOOKUP(ecommerce_order__1[[#This Row],[product_sku]],F:J,5,FALSE) -> 45
A13: ORD-102152 | B13: 01-07-2026 | C13: customer0956@example.com | D13: Ireland | E13: email | F13: FR-7781 | G13: Storm Overtrousers | H13: 1 | I13: 129 | J13: 129 | K13: 410 | L13: GBP | M13: completed | N13: 129 | Q13: =VLOOKUP(ecommerce_order__1[[#This Row],[product_sku]],F:J,5,FALSE) -> 45
A14: ORD-102773 | B14: 02/27/2026 | C14: customer1363@example.com | D14: GB | E14: organic | F14: FR-3345 | G14: CafÃ© Latte Mug | H14: 3 | I14: 116.1 | J14: 348.3 | K14: 340 | L14: GBP | M14: refunded | N14: 116.1 | Q14: =VLOOKUP(ecommerce_order__1[[#This Row],[product_sku]],F:J,5,FALSE) -> 348.3
A15: ORD-102215 | B15: 21-02-2026 | C15: customer1206@example.com | D15: gb | E15: direct | F15: FR-4471 | G15: Alpine Jacket | H15: -3 | I15: 129 | J15: 387 | K15: 640 | L15: GBP | M15: completed | N15: 129 | Q15: =VLOOKUP(ecommerce_order__1[[#This Row],[product_sku]],F:J,5,FALSE) -> 387
A16: ORD-100612 | B16: 05-07-2026 | C16: customer0555@example.com | D16: uk | E16: email | F16: FR-2210 | G16: Trail Softshell | H16: 1 | I16: 45 | J16: 45 | K16: 0.52 | L16: EUR | M16: completed | N16: 45 | Q16: =VLOOKUP(ecommerce_order__1[[#This Row],[product_sku]],F:J,5,FALSE) -> 71.1
A17: ORD-102771 | B17: 11-01-2026 | C17: customer1312@example.com | D17: Ireland | E17: paid_search | F17: FR-1120 | G17: Fell Runner Cap | H17: 1 | I17: 71.1 | J17: 71.1 | K17: 85 | L17: GBP | M17: completed | N17: 71.1 | Q17: =VLOOKUP(ecommerce_order__1[[#This Row],[product_sku]],F:J,5,FALSE) -> 45
A18: ORD-101929 | B18: 19-06-2026 | C18: customer0084@example.com | D18: United Kingdom | E18: organic | F18: FR-7781 | G18: Storm Overtrousers | H18: 1 | I18: 116.1 | J18: 116.1 | K18: 0.41 | L18: GBP | M18: completed | N18: 116.1 | Q18: =VLOOKUP(ecommerce_order__1[[#This Row],[product_sku]],F:J,5,FALSE) -> 45
... A27: ORD-102809 | B27: 23-04-2026 | C27: customer0212@example.com | D27: Germany | E27: organic | F27: FR-5567 | G27: Merino Base Layer | H27: 3 | I27: 89 | J27: 267 | K27: 0.19 | L27: EUR | M27: completed | N27: 89 | Q27: =VLOOKUP(ecommerce_order__1[[#This Row],[product_sku]],F:J,5,FALSE) -> 71.1
A28: ORD-102890 | B28: 09-01-2026 | C28: customer0605@example.com | D28: UK | E28: direct | F28: FR-3345 | G28: CafÃ© Latte Mug | H28: 1 | J28: 21.6 | K28: 340 | L28: GBP | M28: refunded | N28: 21.6 | Q28: =VLOOKUP(ecommerce_order__1[[#This Row],[product_sku]],F:J,5,FALSE) -> 348.3
A29: ORD-100039 | B29: 31-05-2026 | C29: customer0449@example.com | D29: UK | E29: social | F29: FR-8890 | G29: Summit Down Gilet | H29: 2 | I29: 79 | J29: 158 | K29: 0.38 | L29: GBP | M29: completed | N29: 79 | Q29: =VLOOKUP(ecommerce_order__1[[#This Row],[product_sku]],F:J,5,FALSE) -> 21.6
A30: ORD-102776 | B30: 30-06-2026 | C30: customer0321@example.com | D30: GB | E30: direct | F30: FR-8890 | G30: Summit Down Gilet | H30: 3 | I30: 11.25 | J30: 33.75 | K30: 0.38 | L30: GBP | M30: completed | N30: 11.25 | Q30: =VLOOKUP(ecommerce_order__1[[#This Row],[product_sku]],F:J,5,FALSE) -> 21.6
A31: ORD-100053 | B31: 04-04-2026 | C31: customer1166@example.com | D31: gb | E31: social | F31: FR-2210 | G31: Trail Softshell | H31: 1 | J31: 36 | K31: 520 | L31: GBP | M31: completed | Q31: =VLOOKUP(ecommerce_order__1[[#This Row],[product_sku]],F:J,5,FALSE) -> 71.1
A32: ORD-101914 | B32: 13-03-2026 | C32: customer0347@example.com | D32: Germany | E32: paid_search | F32: FR-5567 | G32: Merino Base Layer | H32: 2 | I32: 129 | J32: 258 | K32: 190 | L32: GBP | M32: completed | N32: 129 | Q32: =VLOOKUP(ecommerce_order__1[[#This Row],[product_sku]],F:J,5,FALSE) -> 71.1
A33: ORD-100303 | B33: 17-01-2026 | C33: customer1186@example.com | D33: UK | E33: social | F33: FR-4471 | G33: Alpine Jacket | H33: 1 | I33: 71.1 | J33: 71.1 | K33: 640 | L33: GBP | M33: completed | N33: 71.1 | Q33: =VLOOKUP(ecommerce_order__1[[#This Row],[product_sku]],F:J,5,FALSE) -> 387
A34: ORD-102075 | B34: 01-04-2026 | C34: customer1029@example.com | D34: UK | E34: organic | F34: FR-3345 | G34: CafÃ© Latte Mug | H34: -2 | I34: 45 | J34: -90 | K34: 340 | L34: GBP | M34: completed | N34: 45 | Q34: =VLOOKUP(ecommerce_order__1[[#This Row],[product_sku]],F:J,5,FALSE) -> 348.3
A35: ORD-101025 | B35: 15-02-2026 | C35: customer1144@example.com | D35: United Kingdom | E35: email | F35: FR-4471 | G35: Alpine Jacket | H35: 2 | J35: 160.2 | K35: 640 | L35: EUR | M35: completed | Q35: =VLOOKUP(ecommerce_order__1[[#This Row],[product_sku]],F:J,5,FALSE) -> 387
A36: ORD-101946 | B36: 10-05-2026 | C36: customer1248@example.com | D36: UK | E36: organic | F36: FR-4471 | G36: Alpine Jacket | H36: 2 | J36: 25 | K36: 0.64 | L36: GBP | M36: completed | Q36: =VLOOKUP(ecommerce_order__1[[#This Row],[product_sku]],F:J,5,FALSE) -> 387
A37: ORD-101075 | B37: 03/19/2026 | C37: customer0388@example.com | D37: UK | E37: organic | F37: FR-7781 | G37: Storm Overtrousers | H37: 3 | I37: 149 | J37: 447 | K37: 410 | L37: GBP | M37: completed | N37: 149 | Q37: =VLOOKUP(ecommerce_order__1[[#This Row],[product_sku]],F:J,5,FALSE) -> 45
A38: ORD-101807 | B38: 04/24/2026 | C38: customer1225@example.com | D38: UK | E38: direct | F38: FR-7781 | G38: Storm Overtrousers | H38: 2 | I38: 11.25 | J38: 22.5 | K38: 0.41 | L38: GBP | M38: refunded | N38: 11.25 | Q38: =VLOOKUP(ecommerce_order__1[[#This Row],[product_sku]],F:J,5,FALSE) -> 45
A39: ORD-102879 | B39: 30-03-2026 | C39: customer1087@example.com | D39: ireland | E39: paid_search | F39: FR-7781 | G39: Storm Overtrousers | H39: 1 | I39: 149 | J39: 149 | K39: 410 | L39: GBP | M39: refunded | N39: 149 | Q39: =VLOOKUP(ecommerce_order__1[[#This Row],[product_sku]],F:J,5,FALSE) -> 45
A40: ORD-100229 | B40: 02/14/2026 | C40: customer0706@example.com | D40: gb | E40: paid_search | F40: FR-1120 | G40: Fell Runner Cap | H40: 1 | I40: 80.1 | J40: 80.1 | K40: 85 | L40: GBP | M40: completed | N40: 80.1 | Q40: =VLOOKUP(ecommerce_order__1[[#This Row],[product_sku]],F:J,5,FALSE) -> 45
A41: ORD-101507 | B41: 06/20/2026 | C41: customer0951@example.com | D41: uk | E41: organic | F41: FR-5567 | G41: Merino Base Layer | H41: 1 | I41: 95 | J41: 95 | K41: 0.19 | L41: GBP | M41: completed | N41: 95 | Q41: =VLOOKUP(ecommerce_order__1[[#This Row],[product_sku]],F:J,5,FALSE) -> 71.1
A42: ORD-100281 | B42: 20-06-2026 | C42: customer1318@example.com | D42: gb | E42: organic | F42: FR-7781 | G42: Storm Overtrousers | H42: 3 | I42: 11.25 | J42: 33.75 | K42: 0.41 | L42: GBP | M42: completed | N42: 11.25 | Q42: =VLOOKUP(ecommerce_order__1[[#This Row],[product_sku]],F:J,5,FALSE) -> 45
A43: ORD-100155 | B43: 27-05-2026 | C43: customer0109@example.com | D43: UK | E43: social | F43: FR-4471 | G43: Alpine Jacket | H43: 2 | I43: 21.6 | J43: 43.2 | K43: 0.64 | L43: EUR | M43: refunded | N43: 21.6 | Q43: =VLOOKUP(ecommerce_order__1[[#This Row],[product_sku]],F:J,5,FALSE) -> 387
A44: ORD-102793 | B44: 03-02-2026 | C44: customer0701@example.com | D44: United Kingdom | E44: email | F44: FR-8890 | G44: Summit Down Gilet | H44: 2 | I44: 89 | J44: 178 | K44: 380 | L44: GBP | M44: completed | N44: 89 | Q44: =VLOOKUP(ecommerce_order__1[[#This Row],[product_sku]],F:J,5,FALSE) -> 21.6
A45: ORD-102266 | B45: 19-01-2026 | C45: customer0725@example.com | D45: UK | E45: email | F45: FR-3345 | G45: CafÃ© Latte Mug | H45: 1 | J45: 80.1 | K45: 340 | L45: GBP | M45: completed | Q45: =VLOOKUP(ecommerce_order__1[[#This Row],[product_sku]],F:J,5,FALSE) -> 348.3
A46: ORD-102177 | B46: 06/24/2026 | C46: customer0599@example.com | D46: UK | E46: direct | F46: FR-3345 | G46: CafÃ© Latte Mug | H46: 3 | I46: 129 | J46: 387 | K46: 0.34 | L46: GBP | M46: completed | N46: 129 | Q46: =VLOOKUP(ecommerce_order__1[[#This Row],[product_sku]],F:J,5,FALSE) -> 348.3
A47: ORD-102794 | B47: 21-05-2026 | C47: customer0480@example.com | D47: ireland | E47: paid_search | F47: FR-7781 | G47: Storm Overtrousers | H47: 2 | I47: 129 | J47: 258 | K47: 0.41 | L47: GBP | M47: completed | N47: 129 | Q47: =VLOOKUP(ecommerce_order__1[[#This Row],[product_sku]],F:J,5,FALSE) -> 45
A48: ORD-102860 | B48: 24-03-2026 | C48: customer1378@example.com | D48: UK | E48: direct | F48: FR-4471 | G48: Alpine Jacket | H48: 2 | J48: 171 | K48: 640 | L48: GBP | M48: refunded | Q48: =VLOOKUP(ecommerce_order__1[[#This Row],[product_sku]],F:J,5,FALSE) -> 387
...

Sheet Sheet1
A1: order_id | B1: =VLOOKUP($A$1,'ecommerce-order (1)'!$A:$M,2,FALSE) -> order_date | C1: =VLOOKUP($A$1,'ecommerce-order (1)'!$A:$M,3,FALSE) -> customer_email | D1: =VLOOKUP($A$1,'ecommerce-order (1)'!$A:$M,4,FALSE) -> country | E1: =VLOOKUP($A$1,'ecommerce-order (1)'!$A:$M,5,FALSE) -> channel | F1: =VLOOKUP($A$1,'ecommerce-order (1)'!$A:$M,6,FALSE) -> product_sku | G1: =VLOOKUP($A$1,'ecommerce-order (1)'!$A:$M,7,FALSE) -> product_name | H1: =VLOOKUP($A$1,'ecommerce-order (1)'!$A:$M,8,FALSE) -> quantity | I1: =VLOOKUP($A$1,'ecommerce-order (1)'!$A:$M,9,FALSE) -> unit_price | J1: =VLOOKUP($A$1,'ecommerce-order (1)'!$A:$M,10,FALSE) -> order_total | K1: =VLOOKUP($A$1,'ecommerce-order (1)'!$A:$M,11,FALSE) -> weight | L1: =VLOOKUP($A$1,'ecommerce-order (1)'!$A:$M,12,FALSE) -> currency | M1: =VLOOKUP($A$1,'ecommerce-order (1)'!$A:$M,13,FALSE) -> status | N1: keep using vlookup
A2: ORD-101805 | B2: =VLOOKUP(A2,'ecommerce-order (1)'!$A:$M,2,FALSE) -> 19-03-2026 | C2: =VLOOKUP($A2,'ecommerce-order (1)'!$A:$M,3,FALSE) -> customer0457@example.com | D2: =VLOOKUP($A2,'ecommerce-order (1)'!$A:$M,4,FALSE) -> France | E2: =VLOOKUP($A2,'ecommerce-order (1)'!$A:$M,5,FALSE) -> direct | F2: =VLOOKUP($A2,'ecommerce-order (1)'!$A:$M,6,FALSE) -> FR-9902 | G2: =VLOOKUP($A2,'ecommerce-order (1)'!$A:$M,7,FALSE) -> Trekking Poles | H2: =VLOOKUP($A2,'ecommerce-order (1)'!$A:$M,8,FALSE) -> 1 | I2: =VLOOKUP($A2,'ecommerce-order (1)'!$A:$M,9,FALSE) -> 45 | J2: =VLOOKUP($A2,'ecommerce-order (1)'!$A:$M,10,FALSE) -> 36 | K2: =VLOOKUP($A2,'ecommerce-order (1)'!$A:$M,11,FALSE) -> 520 | L2: =VLOOKUP($A2,'ecommerce-order (1)'!$A:$M,12,FALSE) -> EUR | M2: =VLOOKUP($A2,'ecommerce-order (1)'!$A:$M,13,FALSE) -> completed | N2: =IF(ISNA(VLOOKUP(A2,'ecommerce-order (1)'!A:A,1,FALSE)),"KEEEP","REMOVE") -> REMOVE
A3: ORD-102690 | B3: =VLOOKUP(A3,'ecommerce-order (1)'!$A:$M,2,FALSE) -> 19-05-2026 | C3: =VLOOKUP($A3,'ecommerce-order (1)'!$A:$M,3,FALSE) -> customer0814@example.com | D3: =VLOOKUP($A3,'ecommerce-order (1)'!$A:$M,4,FALSE) -> France | E3: =VLOOKUP($A3,'ecommerce-order (1)'!$A:$M,5,FALSE) -> social | F3: =VLOOKUP($A3,'ecommerce-order (1)'!$A:$M,6,FALSE) -> FR-2210 | G3: =VLOOKUP($A3,'ecommerce-order (1)'!$A:$M,7,FALSE) -> Trail Softshell | H3: =VLOOKUP($A3,'ecommerce-order (1)'!$A:$M,8,FALSE) -> 1 | I3: =VLOOKUP($A3,'ecommerce-order (1)'!$A:$M,9,FALSE) -> 71.1 | J3: =VLOOKUP($A3,'ecommerce-order (1)'!$A:$M,10,FALSE) -> 71.1 | K3: =VLOOKUP($A3,'ecommerce-order (1)'!$A:$M,11,FALSE) -> 0.52 | L3: =VLOOKUP($A3,'ecommerce-order (1)'!$A:$M,12,FALSE) -> GBP | M3: =VLOOKUP($A3,'ecommerce-order (1)'!$A:$M,13,FALSE) -> completed | N3: =IF(ISNA(VLOOKUP(A3,'ecommerce-order (1)'!A:A,1,FALSE)),"KEEEP","REMOVE") -> REMOVE
A4: ORD-101454 | B4: =VLOOKUP(A4,'ecommerce-order (1)'!$A:$M,2,FALSE) -> 14-06-2026 | C4: =VLOOKUP($A4,'ecommerce-order (1)'!$A:$M,3,FALSE) -> customer0858@example.com | D4: =VLOOKUP($A4,'ecommerce-order (1)'!$A:$M,4,FALSE) -> UK | E4: =VLOOKUP($A4,'ecommerce-order (1)'!$A:$M,5,FALSE) -> email | F4: =VLOOKUP($A4,'ecommerce-order (1)'!$A:$M,6,FALSE) -> FR-1120 | G4: =VLOOKUP($A4,'ecommerce-order (1)'!$A:$M,7,FALSE) -> Fell Runner Cap | H4: =VLOOKUP($A4,'ecommerce-order (1)'!$A:$M,8,FALSE) -> 1 | I4: =VLOOKUP($A4,'ecommerce-order (1)'!$A:$M,9,FALSE) -> 0 | J4: =VLOOKUP($A4,'ecommerce-order (1)'!$A:$M,10,FALSE) -> 45 | K4: =VLOOKUP($A4,'ecommerce-order (1)'!$A:$M,11,FALSE) -> 0.085 | L4: =VLOOKUP($A4,'ecommerce-order (1)'!$A:$M,12,FALSE) -> GBP | M4: =VLOOKUP($A4,'ecommerce-order (1)'!$A:$M,13,FALSE) -> completed | N4: =IF(ISNA(VLOOKUP(A4,'ecommerce-order (1)'!A:A,1,FALSE)),"KEEEP","REMOVE") -> REMOVE
A5: ORD-100450 | B5: =VLOOKUP(A5,'ecommerce-order (1)'!$A:$M,2,FALSE) -> 08-01-2026 | C5: =VLOOKUP($A5,'ecommerce-order (1)'!$A:$M,3,FALSE) -> customer0116@example.com | D5: =VLOOKUP($A5,'ecommerce-order (1)'!$A:$M,4,FALSE) -> UK | E5: =VLOOKUP($A5,'ecommerce-order (1)'!$A:$M,5,FALSE) -> organic | F5: =VLOOKUP($A5,'ecommerce-order (1)'!$A:$M,6,FALSE) -> FR-5567 | G5: =VLOOKUP($A5,'ecommerce-order (1)'!$A:$M,7,FALSE) -> Merino Base Layer | H5: =VLOOKUP($A5,'ecommerce-order (1)'!$A:$M,8,FALSE) -> 1 | I5: =VLOOKUP($A5,'ecommerce-order (1)'!$A:$M,9,FALSE) -> 71.1 | J5: =VLOOKUP($A5,'ecommerce-order (1)'!$A:$M,10,FALSE) -> 71.1 | K5: =VLOOKUP($A5,'ecommerce-order (1)'!$A:$M,11,FALSE) -> 190 | L5: =VLOOKUP($A5,'ecommerce-order (1)'!$A:$M,12,FALSE) -> EUR | M5: =VLOOKUP($A5,'ecommerce-order (1)'!$A:$M,13,FALSE) -> completed | N5: =IF(ISNA(VLOOKUP(A5,'ecommerce-order (1)'!A:A,1,FALSE)),"KEEEP","REMOVE") -> REMOVE
A6: ORD-101501 | B6: =VLOOKUP(A6,'ecommerce-order (1)'!$A:$M,2,FALSE) -> 20-05-2026 | C6: =VLOOKUP($A6,'ecommerce-order (1)'!$A:$M,3,FALSE) -> customer1397@example.com | D6: =VLOOKUP($A6,'ecommerce-order (1)'!$A:$M,4,FALSE) -> Ireland | E6: =VLOOKUP($A6,'ecommerce-order (1)'!$A:$M,5,FALSE) -> email | F6: =VLOOKUP($A6,'ecommerce-order (1)'!$A:$M,6,FALSE) -> FR-8890 | G6: =VLOOKUP($A6,'ecommerce-order (1)'!$A:$M,7,FALSE) -> Summit Down Gilet | H6: =VLOOKUP($A6,'ecommerce-order (1)'!$A:$M,8,FALSE) -> 1 | I6: =VLOOKUP($A6,'ecommerce-order (1)'!$A:$M,9,FALSE) -> 21.6 | J6: =VLOOKUP($A6,'ecommerce-order (1)'!$A:$M,10,FALSE) -> 21.6 | K6: =VLOOKUP($A6,'ecommerce-order (1)'!$A:$M,11,FALSE) -> 0.38 | L6: =VLOOKUP($A6,'ecommerce-order (1)'!$A:$M,12,FALSE) -> GBP | M6: =VLOOKUP($A6,'ecommerce-order (1)'!$A:$M,13,FALSE) -> completed | N6: =IF(ISNA(VLOOKUP(A6,'ecommerce-order (1)'!A:A,1,FALSE)),"KEEEP","REMOVE") -> REMOVE
A7: ORD-101788 | B7: =VLOOKUP(A7,'ecommerce-order (1)'!$A:$M,2,FALSE) -> 14-03-2026 | C7: =VLOOKUP($A7,'ecommerce-order (1)'!$A:$M,3,FALSE) -> customer0775@example.com | D7: =VLOOKUP($A7,'ecommerce-order (1)'!$A:$M,4,FALSE) -> GB | E7: =VLOOKUP($A7,'ecommerce-order (1)'!$A:$M,5,FALSE) -> organic | F7: =VLOOKUP($A7,'ecommerce-order (1)'!$A:$M,6,FALSE) -> FR-1120 | G7: =VLOOKUP($A7,'ecommerce-order (1)'!$A:$M,7,FALSE) -> Fell Runner Cap | H7: =VLOOKUP($A7,'ecommerce-order (1)'!$A:$M,8,FALSE) -> 1 | I7: =VLOOKUP($A7,'ecommerce-order (1)'!$A:$M,9,FALSE) -> 45 | J7: =VLOOKUP($A7,'ecommerce-order (1)'!$A:$M,10,FALSE) -> 45 | K7: =VLOOKUP($A7,'ecommerce-order (1)'!$A:$M,11,FALSE) -> 85 | L7: =VLOOKUP($A7,'ecommerce-order (1)'!$A:$M,12,FALSE) -> GBP | M7: =VLOOKUP($A7,'ecommerce-order (1)'!$A:$M,13,FALSE) -> completed | N7: =IF(ISNA(VLOOKUP(A7,'ecommerce-order (1)'!A:A,1,FALSE)),"KEEEP","REMOVE") -> REMOVE
A8: ORD-102657 | B8: =VLOOKUP(A8,'ecommerce-order (1)'!$A:$M,2,FALSE) -> 25-04-2026 | C8: =VLOOKUP($A8,'ecommerce-order (1)'!$A:$M,3,FALSE) -> customer1328@example.com | D8: =VLOOKUP($A8,'ecommerce-order (1)'!$A:$M,4,FALSE) -> GB | E8: =VLOOKUP($A8,'ecommerce-order (1)'!$A:$M,5,FALSE) -> social | F8: =VLOOKUP($A8,'ecommerce-order (1)'!$A:$M,6,FALSE) -> FR-1120 | G8: =VLOOKUP($A8,'ecommerce-order (1)'!$A:$M,7,FALSE) -> Fell Runner Cap | H8: =VLOOKUP($A8,'ecommerce-order (1)'!$A:$M,8,FALSE) -> 3 | I8: =VLOOKUP($A8,'ecommerce-order (1)'!$A:$M,9,FALSE) -> 85.5 | J8: =VLOOKUP($A8,'ecommerce-order (1)'!$A:$M,10,FALSE) -> 256.5 | K8: =VLOOKUP($A8,'ecommerce-order (1)'!$A:$M,11,FALSE) -> 0.085 | L8: =VLOOKUP($A8,'ecommerce-order (1)'!$A:$M,12,FALSE) -> GBP | M8: =VLOOKUP($A8,'ecommerce-order (1)'!$A:$M,13,FALSE) -> refunded | N8: =IF(ISNA(VLOOKUP(A8,'ecommerce-order (1)'!A:A,1,FALSE)),"KEEEP","REMOVE") -> REMOVE
A9: ORD-102047 | B9: =VLOOKUP(A9,'ecommerce-order (1)'!$A:$M,2,FALSE) -> 20-05-2026 | C9: =VLOOKUP($A9,'ecommerce-order (1)'!$A:$M,3,FALSE) -> customer0760@example.com | D9: =VLOOKUP($A9,'ecommerce-order (1)'!$A:$M,4,FALSE) -> ireland | E9: =VLOOKUP($A9,'ecommerce-order (1)'!$A:$M,5,FALSE) -> organic | F9: =VLOOKUP($A9,'ecommerce-order (1)'!$A:$M,6,FALSE) -> FR-1120 | G9: =VLOOKUP($A9,'ecommerce-order (1)'!$A:$M,7,FALSE) -> Fell Runner Cap | H9: =VLOOKUP($A9,'ecommerce-order (1)'!$A:$M,8,FALSE) -> 2 | I9: =VLOOKUP($A9,'ecommerce-order (1)'!$A:$M,9,FALSE) -> 134.1 | J9: =VLOOKUP($A9,'ecommerce-order (1)'!$A:$M,10,FALSE) -> 268.2 | K9: =VLOOKUP($A9,'ecommerce-order (1)'!$A:$M,11,FALSE) -> 0.085 | L9: =VLOOKUP($A9,'ecommerce-order (1)'!$A:$M,12,FALSE) -> EUR | M9: =VLOOKUP($A9,'ecommerce-order (1)'!$A:$M,13,FALSE) -> refunded | N9: =IF(ISNA(VLOOKUP(A9,'ecommerce-order (1)'!A:A,1,FALSE)),"KEEEP","REMOVE") -> REMOVE
A10: ORD-102650 | B10: =VLOOKUP(A10,'ecommerce-order (1)'!$A:$M,2,FALSE) -> 02-04-2026 | C10: =VLOOKUP($A10,'ecommerce-order (1)'!$A:$M,3,FALSE) -> customer0013@example.com | D10: =VLOOKUP($A10,'ecommerce-order (1)'!$A:$M,4,FALSE) -> gb | E10: =VLOOKUP($A10,'ecommerce-order (1)'!$A:$M,5,FALSE) -> paid_search | F10: =VLOOKUP($A10,'ecommerce-order (1)'!$A:$M,6,FALSE) -> FR-5567 | G10: =VLOOKUP($A10,'ecommerce-order (1)'!$A:$M,7,FALSE) -> Merino Base Layer | H10: =VLOOKUP($A10,'ecommerce-order (1)'!$A:$M,8,FALSE) -> 1 | I10: =VLOOKUP($A10,'ecommerce-order (1)'!$A:$M,9,FALSE) -> 24 | J10: =VLOOKUP($A10,'ecommerce-order (1)'!$A:$M,10,FALSE) -> 24 | K10: =VLOOKUP($A10,'ecommerce-order (1)'!$A:$M,11,FALSE) -> 190 | L10: =VLOOKUP($A10,'ecommerce-order (1)'!$A:$M,12,FALSE) -> GBP | M10: =VLOOKUP($A10,'ecommerce-order (1)'!$A:$M,13,FALSE) -> completed | N10: =IF(ISNA(VLOOKUP(A10,'ecommerce-order (1)'!A:A,1,FALSE)),"KEEEP","REMOVE") -> REMOVE
A11: ORD-102734 | B11: =VLOOKUP(A11,'ecommerce-order (1)'!$A:$M,2,FALSE) -> 16-02-2026 | C11: =VLOOKUP($A11,'ecommerce-order (1)'!$A:$M,3,FALSE) -> customer0805@example.com | D11: =VLOOKUP($A11,'ecommerce-order (1)'!$A:$M,4,FALSE) -> UK | E11: =VLOOKUP($A11,'ecommerce-order (1)'!$A:$M,5,FALSE) -> paid_search | F11: =VLOOKUP($A11,'ecommerce-order (1)'!$A:$M,6,FALSE) -> FR-5567 | G11: =VLOOKUP($A11,'ecommerce-order (1)'!$A:$M,7,FALSE) -> Merino Base Layer | H11: =VLOOKUP($A11,'ecommerce-order (1)'!$A:$M,8,FALSE) -> 1 | I11: =VLOOKUP($A11,'ecommerce-order (1)'!$A:$M,9,FALSE) -> 95 | J11: =VLOOKUP($A11,'ecommerce-order (1)'!$A:$M,10,FALSE) -> 95 | K11: =VLOOKUP($A11,'ecommerce-order (1)'!$A:$M,11,FALSE) -> 190 | L11: =VLOOKUP($A11,'ecommerce-order (1)'!$A:$M,12,FALSE) -> EUR | M11: =VLOOKUP($A11,'ecommerce-order (1)'!$A:$M,13,FALSE) -> refunded | N11: =IF(ISNA(VLOOKUP(A11,'ecommerce-order (1)'!A:A,1,FALSE)),"KEEEP","REMOVE") -> REMOVE
A12: ORD-102012 | B12: =VLOOKUP(A12,'ecommerce-order (1)'!$A:$M,2,FALSE) -> 21-04-2026 | C12: =VLOOKUP($A12,'ecommerce-order (1)'!$A:$M,3,FALSE) -> customer0123@example.com | D12: =VLOOKUP($A12,'ecommerce-order (1)'!$A:$M,4,FALSE) -> UK | E12: =VLOOKUP($A12,'ecommerce-order (1)'!$A:$M,5,FALSE) -> email | F12: =VLOOKUP($A12,'ecommerce-order (1)'!$A:$M,6,FALSE) -> FR-7781 | G12: =VLOOKUP($A12,'ecommerce-order (1)'!$A:$M,7,FALSE) -> Storm Overtrousers | H12: =VLOOKUP($A12,'ecommerce-order (1)'!$A:$M,8,FALSE) -> 1 | I12: =VLOOKUP($A12,'ecommerce-order (1)'!$A:$M,9,FALSE) -> 45 | J12: =VLOOKUP($A12,'ecommerce-order (1)'!$A:$M,10,FALSE) -> 45 | K12: =VLOOKUP($A12,'ecommerce-order (1)'!$A:$M,11,FALSE) -> 0.41 | L12: =VLOOKUP($A12,'ecommerce-order (1)'!$A:$M,12,FALSE) -> GBP | M12: =VLOOKUP($A12,'ecommerce-order (1)'!$A:$M,13,FALSE) -> completed | N12: =IF(ISNA(VLOOKUP(A12,'ecommerce-order (1)'!A:A,1,FALSE)),"KEEEP","REMOVE") -> REMOVE
A13: ORD-102152 | B13: =VLOOKUP(A13,'ecommerce-order (1)'!$A:$M,2,FALSE) -> 01-07-2026 | C13: =VLOOKUP($A13,'ecommerce-order (1)'!$A:$M,3,FALSE) -> customer0956@example.com | D13: =VLOOKUP($A13,'ecommerce-order (1)'!$A:$M,4,FALSE) -> Ireland | E13: =VLOOKUP($A13,'ecommerce-order (1)'!$A:$M,5,FALSE) -> email | F13: =VLOOKUP($A13,'ecommerce-order (1)'!$A:$M,6,FALSE) -> FR-7781 | G13: =VLOOKUP($A13,'ecommerce-order (1)'!$A:$M,7,FALSE) -> Storm Overtrousers | H13: =VLOOKUP($A13,'ecommerce-order (1)'!$A:$M,8,FALSE) -> 1 | I13: =VLOOKUP($A13,'ecommerce-order (1)'!$A:$M,9,FALSE) -> 129 | J13: =VLOOKUP($A13,'ecommerce-order (1)'!$A:$M,10,FALSE) -> 129 | K13: =VLOOKUP($A13,'ecommerce-order (1)'!$A:$M,11,FALSE) -> 410 | L13: =VLOOKUP($A13,'ecommerce-order (1)'!$A:$M,12,FALSE) -> GBP | M13: =VLOOKUP($A13,'ecommerce-order (1)'!$A:$M,13,FALSE) -> completed | N13: =IF(ISNA(VLOOKUP(A13,'ecommerce-order (1)'!A:A,1,FALSE)),"KEEEP","REMOVE") -> REMOVE
... A203: ORD-102012 | B203: =VLOOKUP(A203,'ecommerce-order (1)'!$A:$M,2,FALSE) -> 21-04-2026 | C203: =VLOOKUP($A203,'ecommerce-order (1)'!$A:$M,3,FALSE) -> customer0123@example.com | D203: =VLOOKUP($A203,'ecommerce-order (1)'!$A:$M,4,FALSE) -> UK | E203: =VLOOKUP($A203,'ecommerce-order (1)'!$A:$M,5,FALSE) -> email | F203: =VLOOKUP($A203,'ecommerce-order (1)'!$A:$M,6,FALSE) -> FR-7781 | G203: =VLOOKUP($A203,'ecommerce-order (1)'!$A:$M,7,FALSE) -> Storm Overtrousers | H203: =VLOOKUP($A203,'ecommerce-order (1)'!$A:$M,8,FALSE) -> 1 | I203: =VLOOKUP($A203,'ecommerce-order (1)'!$A:$M,9,FALSE) -> 45 | J203: =VLOOKUP($A203,'ecommerce-order (1)'!$A:$M,10,FALSE) -> 45 | K203: =VLOOKUP($A203,'ecommerce-order (1)'!$A:$M,11,FALSE) -> 0.41 | L203: =VLOOKUP($A203,'ecommerce-order (1)'!$A:$M,12,FALSE) -> GBP | M203: =VLOOKUP($A203,'ecommerce-order (1)'!$A:$M,13,FALSE) -> completed | N203: =IF(ISNA(VLOOKUP(A203,'ecommerce-order (1)'!A:A,1,FALSE)),"KEEEP","REMOVE") -> REMOVE
